[2021-03-23 15:54:26,666] {taskinstance.py:851} INFO - Dependencies all met for <TaskInstance: EDGAR-Annotation-Pipeline.Cleanup 2021-03-23T22:53:45.650465+00:00 [queued]>
[2021-03-23 15:54:26,675] {taskinstance.py:851} INFO - Dependencies all met for <TaskInstance: EDGAR-Annotation-Pipeline.Cleanup 2021-03-23T22:53:45.650465+00:00 [queued]>
[2021-03-23 15:54:26,675] {taskinstance.py:1042} INFO - 
--------------------------------------------------------------------------------
[2021-03-23 15:54:26,675] {taskinstance.py:1043} INFO - Starting attempt 1 of 1
[2021-03-23 15:54:26,675] {taskinstance.py:1044} INFO - 
--------------------------------------------------------------------------------
[2021-03-23 15:54:26,682] {taskinstance.py:1063} INFO - Executing <Task(PythonOperator): Cleanup> on 2021-03-23T22:53:45.650465+00:00
[2021-03-23 15:54:26,684] {standard_task_runner.py:52} INFO - Started process 40125 to run task
[2021-03-23 15:54:26,692] {standard_task_runner.py:76} INFO - Running: ['airflow', 'tasks', 'run', 'EDGAR-Annotation-Pipeline', 'Cleanup', '2021-03-23T22:53:45.650465+00:00', '--job-id', '60', '--pool', 'default_pool', '--raw', '--subdir', 'DAGS_FOLDER/edgar_annotation.py', '--cfg-path', '/var/folders/_j/s8vbc0cs1fvgclq8hnvtq1wm0000gn/T/tmpircuwl87', '--error-file', '/var/folders/_j/s8vbc0cs1fvgclq8hnvtq1wm0000gn/T/tmpmj_nhz9n']
[2021-03-23 15:54:26,694] {standard_task_runner.py:77} INFO - Job 60: Subtask Cleanup
[2021-03-23 15:54:26,728] {logging_mixin.py:104} INFO - Running <TaskInstance: EDGAR-Annotation-Pipeline.Cleanup 2021-03-23T22:53:45.650465+00:00 [running]> on host prathyushas-mbp.home
[2021-03-23 15:54:26,752] {taskinstance.py:1255} INFO - Exporting the following env vars:
AIRFLOW_CTX_DAG_OWNER=airflow
AIRFLOW_CTX_DAG_ID=EDGAR-Annotation-Pipeline
AIRFLOW_CTX_TASK_ID=Cleanup
AIRFLOW_CTX_EXECUTION_DATE=2021-03-23T22:53:45.650465+00:00
AIRFLOW_CTX_DAG_RUN_ID=manual__2021-03-23T22:53:45.650465+00:00
[2021-03-23 15:54:26,753] {taskinstance.py:1455} ERROR - read_csv() got an unexpected keyword argument 'index'
Traceback (most recent call last):
  File "/Users/prathyusha/Desktop/pranathi/Assignment2/airflow_edgar/edgar_env/lib/python3.8/site-packages/airflow/models/taskinstance.py", line 1112, in _run_raw_task
    self._prepare_and_execute_task_with_callbacks(context, task)
  File "/Users/prathyusha/Desktop/pranathi/Assignment2/airflow_edgar/edgar_env/lib/python3.8/site-packages/airflow/models/taskinstance.py", line 1285, in _prepare_and_execute_task_with_callbacks
    result = self._execute_task(context, task_copy)
  File "/Users/prathyusha/Desktop/pranathi/Assignment2/airflow_edgar/edgar_env/lib/python3.8/site-packages/airflow/models/taskinstance.py", line 1315, in _execute_task
    result = task_copy.execute(context=context)
  File "/Users/prathyusha/Desktop/pranathi/Assignment2/airflow_edgar/edgar_env/lib/python3.8/site-packages/airflow/operators/python.py", line 117, in execute
    return_value = self.execute_callable()
  File "/Users/prathyusha/Desktop/pranathi/Assignment2/airflow_edgar/edgar_env/lib/python3.8/site-packages/airflow/operators/python.py", line 128, in execute_callable
    return self.python_callable(*self.op_args, **self.op_kwargs)
  File "/Users/prathyusha/Desktop/pranathi/Assignment2/airflow_edgar/dags/edgar_annotation.py", line 127, in sentiment
    final_df=pd.read_csv('/tmp/final_df.csv',index=False)
TypeError: read_csv() got an unexpected keyword argument 'index'
[2021-03-23 15:54:26,758] {taskinstance.py:1496} INFO - Marking task as FAILED. dag_id=EDGAR-Annotation-Pipeline, task_id=Cleanup, execution_date=20210323T225345, start_date=20210323T225426, end_date=20210323T225426
[2021-03-23 15:54:26,791] {local_task_job.py:146} INFO - Task exited with return code 1
