[2021-03-23 00:01:00,403] {taskinstance.py:851} INFO - Dependencies all met for <TaskInstance: EDGAR-Annotation-Pipeline.DownloadDataFromCloud 2021-03-23T07:00:35.927390+00:00 [queued]>
[2021-03-23 00:01:00,408] {taskinstance.py:851} INFO - Dependencies all met for <TaskInstance: EDGAR-Annotation-Pipeline.DownloadDataFromCloud 2021-03-23T07:00:35.927390+00:00 [queued]>
[2021-03-23 00:01:00,408] {taskinstance.py:1042} INFO - 
--------------------------------------------------------------------------------
[2021-03-23 00:01:00,408] {taskinstance.py:1043} INFO - Starting attempt 1 of 1
[2021-03-23 00:01:00,408] {taskinstance.py:1044} INFO - 
--------------------------------------------------------------------------------
[2021-03-23 00:01:00,414] {taskinstance.py:1063} INFO - Executing <Task(PythonOperator): DownloadDataFromCloud> on 2021-03-23T07:00:35.927390+00:00
[2021-03-23 00:01:00,416] {standard_task_runner.py:52} INFO - Started process 36484 to run task
[2021-03-23 00:01:00,426] {standard_task_runner.py:76} INFO - Running: ['airflow', 'tasks', 'run', 'EDGAR-Annotation-Pipeline', 'DownloadDataFromCloud', '2021-03-23T07:00:35.927390+00:00', '--job-id', '55', '--pool', 'default_pool', '--raw', '--subdir', 'DAGS_FOLDER/edgar_annotation.py', '--cfg-path', '/var/folders/_j/s8vbc0cs1fvgclq8hnvtq1wm0000gn/T/tmpd5_85rka', '--error-file', '/var/folders/_j/s8vbc0cs1fvgclq8hnvtq1wm0000gn/T/tmpkvrbjo6t']
[2021-03-23 00:01:00,428] {standard_task_runner.py:77} INFO - Job 55: Subtask DownloadDataFromCloud
[2021-03-23 00:01:00,459] {logging_mixin.py:104} INFO - Running <TaskInstance: EDGAR-Annotation-Pipeline.DownloadDataFromCloud 2021-03-23T07:00:35.927390+00:00 [running]> on host prathyushas-mbp.home
[2021-03-23 00:01:00,480] {taskinstance.py:1255} INFO - Exporting the following env vars:
AIRFLOW_CTX_DAG_OWNER=airflow
AIRFLOW_CTX_DAG_ID=EDGAR-Annotation-Pipeline
AIRFLOW_CTX_TASK_ID=DownloadDataFromCloud
AIRFLOW_CTX_EXECUTION_DATE=2021-03-23T07:00:35.927390+00:00
AIRFLOW_CTX_DAG_RUN_ID=manual__2021-03-23T07:00:35.927390+00:00
[2021-03-23 00:01:00,518] {credentials.py:1222} INFO - Found credentials in shared credentials file: ~/.aws/credentials
[2021-03-23 00:01:00,580] {taskinstance.py:1455} ERROR - No option 'downloadpath' in section: 'main1'
Traceback (most recent call last):
  File "/Users/prathyusha/opt/anaconda3/lib/python3.8/configparser.py", line 789, in get
    value = d[option]
  File "/Users/prathyusha/opt/anaconda3/lib/python3.8/collections/__init__.py", line 898, in __getitem__
    return self.__missing__(key)            # support subclasses that define __missing__
  File "/Users/prathyusha/opt/anaconda3/lib/python3.8/collections/__init__.py", line 890, in __missing__
    raise KeyError(key)
KeyError: 'downloadpath'

During handling of the above exception, another exception occurred:

Traceback (most recent call last):
  File "/Users/prathyusha/Desktop/pranathi/Assignment2/airflow_edgar/edgar_env/lib/python3.8/site-packages/airflow/models/taskinstance.py", line 1112, in _run_raw_task
    self._prepare_and_execute_task_with_callbacks(context, task)
  File "/Users/prathyusha/Desktop/pranathi/Assignment2/airflow_edgar/edgar_env/lib/python3.8/site-packages/airflow/models/taskinstance.py", line 1285, in _prepare_and_execute_task_with_callbacks
    result = self._execute_task(context, task_copy)
  File "/Users/prathyusha/Desktop/pranathi/Assignment2/airflow_edgar/edgar_env/lib/python3.8/site-packages/airflow/models/taskinstance.py", line 1315, in _execute_task
    result = task_copy.execute(context=context)
  File "/Users/prathyusha/Desktop/pranathi/Assignment2/airflow_edgar/edgar_env/lib/python3.8/site-packages/airflow/operators/python.py", line 117, in execute
    return_value = self.execute_callable()
  File "/Users/prathyusha/Desktop/pranathi/Assignment2/airflow_edgar/edgar_env/lib/python3.8/site-packages/airflow/operators/python.py", line 128, in execute_callable
    return self.python_callable(*self.op_args, **self.op_kwargs)
  File "/Users/prathyusha/Desktop/pranathi/Assignment2/airflow_edgar/dags/edgar_annotation.py", line 37, in download
    parent_dir = config.get('main1', 'downloadpath')
  File "/Users/prathyusha/opt/anaconda3/lib/python3.8/configparser.py", line 792, in get
    raise NoOptionError(option, section)
configparser.NoOptionError: No option 'downloadpath' in section: 'main1'
[2021-03-23 00:01:00,594] {taskinstance.py:1496} INFO - Marking task as FAILED. dag_id=EDGAR-Annotation-Pipeline, task_id=DownloadDataFromCloud, execution_date=20210323T070035, start_date=20210323T070100, end_date=20210323T070100
[2021-03-23 00:01:00,650] {local_task_job.py:146} INFO - Task exited with return code 1
