[2021-03-23 20:28:51,885] {taskinstance.py:851} INFO - Dependencies all met for <TaskInstance: EDGAR-Annotation-Pipeline.PushDataToCloud 2021-03-24T03:23:07.157250+00:00 [queued]>
[2021-03-23 20:28:51,891] {taskinstance.py:851} INFO - Dependencies all met for <TaskInstance: EDGAR-Annotation-Pipeline.PushDataToCloud 2021-03-24T03:23:07.157250+00:00 [queued]>
[2021-03-23 20:28:51,891] {taskinstance.py:1042} INFO - 
--------------------------------------------------------------------------------
[2021-03-23 20:28:51,891] {taskinstance.py:1043} INFO - Starting attempt 1 of 1
[2021-03-23 20:28:51,891] {taskinstance.py:1044} INFO - 
--------------------------------------------------------------------------------
[2021-03-23 20:28:51,896] {taskinstance.py:1063} INFO - Executing <Task(PythonOperator): PushDataToCloud> on 2021-03-24T03:23:07.157250+00:00
[2021-03-23 20:28:51,899] {standard_task_runner.py:52} INFO - Started process 45894 to run task
[2021-03-23 20:28:51,910] {standard_task_runner.py:76} INFO - Running: ['airflow', 'tasks', 'run', 'EDGAR-Annotation-Pipeline', 'PushDataToCloud', '2021-03-24T03:23:07.157250+00:00', '--job-id', '98', '--pool', 'default_pool', '--raw', '--subdir', 'DAGS_FOLDER/edgar_annotation.py', '--cfg-path', '/var/folders/_j/s8vbc0cs1fvgclq8hnvtq1wm0000gn/T/tmphkei5hlz', '--error-file', '/var/folders/_j/s8vbc0cs1fvgclq8hnvtq1wm0000gn/T/tmps2piov95']
[2021-03-23 20:28:51,912] {standard_task_runner.py:77} INFO - Job 98: Subtask PushDataToCloud
[2021-03-23 20:28:51,950] {logging_mixin.py:104} INFO - Running <TaskInstance: EDGAR-Annotation-Pipeline.PushDataToCloud 2021-03-24T03:23:07.157250+00:00 [running]> on host prathyushas-mbp.home
[2021-03-23 20:28:51,974] {taskinstance.py:1255} INFO - Exporting the following env vars:
AIRFLOW_CTX_DAG_OWNER=airflow
AIRFLOW_CTX_DAG_ID=EDGAR-Annotation-Pipeline
AIRFLOW_CTX_TASK_ID=PushDataToCloud
AIRFLOW_CTX_EXECUTION_DATE=2021-03-24T03:23:07.157250+00:00
AIRFLOW_CTX_DAG_RUN_ID=manual__2021-03-24T03:23:07.157250+00:00
[2021-03-23 20:28:52,025] {credentials.py:1222} INFO - Found credentials in shared credentials file: ~/.aws/credentials
[2021-03-23 20:28:56,939] {local_task_job.py:187} WARNING - State of this instance has been externally set to failed. Terminating instance.
[2021-03-23 20:28:56,946] {process_utils.py:100} INFO - Sending Signals.SIGTERM to GPID 45894
[2021-03-23 20:28:56,946] {taskinstance.py:1239} ERROR - Received SIGTERM. Terminating subprocesses.
[2021-03-23 20:28:57,007] {process_utils.py:66} INFO - Process psutil.Process(pid=45894, status='terminated', exitcode=0, started='20:28:51') (45894) terminated with exit code 0
