[2021-03-23 17:04:29,178] {taskinstance.py:851} INFO - Dependencies all met for <TaskInstance: EDGAR-Annotation-Pipeline.Annotation 2021-03-24T00:03:45.888381+00:00 [queued]>
[2021-03-23 17:04:29,183] {taskinstance.py:851} INFO - Dependencies all met for <TaskInstance: EDGAR-Annotation-Pipeline.Annotation 2021-03-24T00:03:45.888381+00:00 [queued]>
[2021-03-23 17:04:29,183] {taskinstance.py:1042} INFO - 
--------------------------------------------------------------------------------
[2021-03-23 17:04:29,183] {taskinstance.py:1043} INFO - Starting attempt 1 of 1
[2021-03-23 17:04:29,183] {taskinstance.py:1044} INFO - 
--------------------------------------------------------------------------------
[2021-03-23 17:04:29,189] {taskinstance.py:1063} INFO - Executing <Task(PythonOperator): Annotation> on 2021-03-24T00:03:45.888381+00:00
[2021-03-23 17:04:29,191] {standard_task_runner.py:52} INFO - Started process 42872 to run task
[2021-03-23 17:04:29,200] {standard_task_runner.py:76} INFO - Running: ['airflow', 'tasks', 'run', 'EDGAR-Annotation-Pipeline', 'Annotation', '2021-03-24T00:03:45.888381+00:00', '--job-id', '86', '--pool', 'default_pool', '--raw', '--subdir', 'DAGS_FOLDER/edgar_annotation.py', '--cfg-path', '/var/folders/_j/s8vbc0cs1fvgclq8hnvtq1wm0000gn/T/tmp62b6x5se', '--error-file', '/var/folders/_j/s8vbc0cs1fvgclq8hnvtq1wm0000gn/T/tmpmpe00bu_']
[2021-03-23 17:04:29,201] {standard_task_runner.py:77} INFO - Job 86: Subtask Annotation
[2021-03-23 17:04:29,230] {logging_mixin.py:104} INFO - Running <TaskInstance: EDGAR-Annotation-Pipeline.Annotation 2021-03-24T00:03:45.888381+00:00 [running]> on host prathyushas-mbp.home
[2021-03-23 17:04:29,251] {taskinstance.py:1255} INFO - Exporting the following env vars:
AIRFLOW_CTX_DAG_OWNER=airflow
AIRFLOW_CTX_DAG_ID=EDGAR-Annotation-Pipeline
AIRFLOW_CTX_TASK_ID=Annotation
AIRFLOW_CTX_EXECUTION_DATE=2021-03-24T00:03:45.888381+00:00
AIRFLOW_CTX_DAG_RUN_ID=manual__2021-03-24T00:03:45.888381+00:00
[2021-03-23 17:55:10,859] {taskinstance.py:1455} ERROR - [Errno 50] Network is down
Traceback (most recent call last):
  File "/Users/prathyusha/Desktop/pranathi/Assignment2/airflow_edgar/edgar_env/lib/python3.8/site-packages/airflow/models/taskinstance.py", line 1112, in _run_raw_task
    self._prepare_and_execute_task_with_callbacks(context, task)
  File "/Users/prathyusha/Desktop/pranathi/Assignment2/airflow_edgar/edgar_env/lib/python3.8/site-packages/airflow/models/taskinstance.py", line 1285, in _prepare_and_execute_task_with_callbacks
    result = self._execute_task(context, task_copy)
  File "/Users/prathyusha/Desktop/pranathi/Assignment2/airflow_edgar/edgar_env/lib/python3.8/site-packages/airflow/models/taskinstance.py", line 1315, in _execute_task
    result = task_copy.execute(context=context)
  File "/Users/prathyusha/Desktop/pranathi/Assignment2/airflow_edgar/edgar_env/lib/python3.8/site-packages/airflow/operators/python.py", line 117, in execute
    return_value = self.execute_callable()
  File "/Users/prathyusha/Desktop/pranathi/Assignment2/airflow_edgar/edgar_env/lib/python3.8/site-packages/airflow/operators/python.py", line 128, in execute_callable
    return self.python_callable(*self.op_args, **self.op_kwargs)
  File "/Users/prathyusha/Desktop/pranathi/Assignment2/airflow_edgar/dags/edgar_annotation.py", line 161, in sentiment
    copy_df=final_df.apply(lambda row: positivity(row),axis=1)
  File "/Users/prathyusha/Desktop/pranathi/Assignment2/airflow_edgar/edgar_env/lib/python3.8/site-packages/pandas/core/frame.py", line 7765, in apply
    return op.get_result()
  File "/Users/prathyusha/Desktop/pranathi/Assignment2/airflow_edgar/edgar_env/lib/python3.8/site-packages/pandas/core/apply.py", line 185, in get_result
    return self.apply_standard()
  File "/Users/prathyusha/Desktop/pranathi/Assignment2/airflow_edgar/edgar_env/lib/python3.8/site-packages/pandas/core/apply.py", line 276, in apply_standard
    results, res_index = self.apply_series_generator()
  File "/Users/prathyusha/Desktop/pranathi/Assignment2/airflow_edgar/edgar_env/lib/python3.8/site-packages/pandas/core/apply.py", line 290, in apply_series_generator
    results[i] = self.f(v)
  File "/Users/prathyusha/Desktop/pranathi/Assignment2/airflow_edgar/dags/edgar_annotation.py", line 161, in <lambda>
    copy_df=final_df.apply(lambda row: positivity(row),axis=1)
  File "/Users/prathyusha/Desktop/pranathi/Assignment2/airflow_edgar/dags/edgar_annotation.py", line 151, in positivity
    response = conn.getresponse()
  File "/Users/prathyusha/opt/anaconda3/lib/python3.8/http/client.py", line 1347, in getresponse
    response.begin()
  File "/Users/prathyusha/opt/anaconda3/lib/python3.8/http/client.py", line 307, in begin
    version, status, reason = self._read_status()
  File "/Users/prathyusha/opt/anaconda3/lib/python3.8/http/client.py", line 268, in _read_status
    line = str(self.fp.readline(_MAXLINE + 1), "iso-8859-1")
  File "/Users/prathyusha/opt/anaconda3/lib/python3.8/socket.py", line 669, in readinto
    return self._sock.recv_into(b)
  File "/Users/prathyusha/opt/anaconda3/lib/python3.8/ssl.py", line 1241, in recv_into
    return self.read(nbytes, buffer)
  File "/Users/prathyusha/opt/anaconda3/lib/python3.8/ssl.py", line 1099, in read
    return self._sslobj.read(len, buffer)
OSError: [Errno 50] Network is down
[2021-03-23 17:55:10,949] {taskinstance.py:1496} INFO - Marking task as FAILED. dag_id=EDGAR-Annotation-Pipeline, task_id=Annotation, execution_date=20210324T000345, start_date=20210324T000429, end_date=20210324T005510
[2021-03-23 17:55:10,979] {local_task_job.py:146} INFO - Task exited with return code 1
